<?xml version="1.0" ?>
<robot name="potter" xmlns:xacro="http://ros.org/wiki/xacro">
  <xacro:include filename="$(find potter_description)/urdf/potter.gazebo.xacro"/>

  <link name="base_footprint"/>

  <joint name="base_joint" type="fixed">
    <parent link="base_footprint"/>
    <child link="base_link"/>
    <origin xyz="0.0 0.0 0.010" rpy="0 0 0"/>
  </joint>

  <link
    name="base_link">
    <inertial>
      <origin
        xyz="-0.120080357398591 -0.586886874304 0.0796377824349438"
        rpy="0 0 0" />
      <mass
        value="9.14455558385384" />
      <inertia
        ixx="0.188342414177923"
        ixy="-0.00224550467699626"
        ixz="0.0458582138362113"
        iyy="0.280000071911791"
        iyz="-0.00175136226771816"
        izz="0.288397145801752" />
    </inertial>
    <visual>
      <origin
        xyz="0 0 0"
        rpy="0 0 0" />
      <geometry>
        <mesh
          filename="package://potter_description/meshes/base_link.STL" />
      </geometry>
      <material
        name="">
        <color
          rgba="0.792156862745098 0.819607843137255 0.933333333333333 1" />
      </material>
    </visual>
    <collision>
      <origin
        xyz="0 0 0"
        rpy="0 0 0" />
      <geometry>
        <mesh
          filename="package://potter_description/meshes/base_link.STL" />
      </geometry>
    </collision>
  </link>
  
  <link
    name="roda_direita">
    <inertial>
      <origin
        xyz="0.000340924586355457 0.00046328993449625 -0.0199805356473918"
        rpy="0 0 0" />
      <mass
        value="0.287619024392822" />
      <inertia
        ixx="0.000388411933483959"
        ixy="8.02432065699622E-11"
        ixz="1.90860427722761E-09"
        iyy="0.00038841198347906"
        iyz="2.59364442995176E-09"
        izz="0.000717036148051891" />
    </inertial>
    <visual>
      <origin
        xyz="0 0 0"
        rpy="0 0 0" />
      <geometry>
        <mesh
          filename="package://potter_description/meshes/roda_direita.STL" />
      </geometry>
      <material
        name="">
        <color
          rgba="0.792156862745098 0.819607843137255 0.933333333333333 1" />
      </material>
    </visual>
    <collision>
      <origin
        xyz="0 0 0"
        rpy="0 0 0" />
      <geometry>
        <mesh
          filename="package://potter_description/meshes/roda_direita.STL" />
      </geometry>
    </collision>
  </link>
  
  <joint
    name="rodadireita"
    type="continuous">
    <origin
      xyz="-0.21335 -0.3315 -0.020509"
      rpy="-1.5708 0.16486 -1.0187E-17" />
    <parent
      link="base_link" />
    <child
      link="roda_direita" />
    <axis
      xyz="0 0 -1" />
  </joint>
  
  <link
    name="roda_esquerda">
    <inertial>
      <origin
        xyz="0.000340924586351654 0.000463289934497416 0.0210452055367201"
        rpy="0 0 0" />
      <mass
        value="0.287619024392823" />
      <inertia
        ixx="0.00038841193348396"
        ixy="8.02432065589412E-11"
        ixz="1.90860428583043E-09"
        iyy="0.00038841198347906"
        iyz="2.59364442982349E-09"
        izz="0.000717036148051891" />
    </inertial>
    <visual>
      <origin
        xyz="0 0 0"
        rpy="0 0 0" />
      <geometry>
        <mesh
          filename="package://potter_description/meshes/roda_esquerda.STL" />
      </geometry>
      <material
        name="">
        <color
          rgba="0.792156862745098 0.819607843137255 0.933333333333333 1" />
      </material>
    </visual>
    <collision>
      <origin
        xyz="0 0 0"
        rpy="0 0 0" />
      <geometry>
        <mesh
          filename="package://potter_description/meshes/roda_esquerda.STL" />
      </geometry>
    </collision>
  </link>
  
  <joint
    name="rodaesquerda"
    type="continuous">
    <origin
      xyz="-0.21903 -0.78921 -0.020325"
      rpy="-1.5615 0.33848 3.1359" />
    <parent
      link="base_link" />
    <child
      link="roda_esquerda" />
    <axis
      xyz="0 0 1" />
  </joint>
  
  <link
    name="roda_traseira">
    <inertial>
      <origin
        xyz="-0.00393732848174855 0.0351667341122072 0.0127005467610188"
        rpy="0 0 0" />
      <mass
        value="0.179276619183742" />
      <inertia
        ixx="9.35648790378295E-05"
        ixy="-7.45002064243031E-07"
        ixz="-6.90490734515864E-08"
        iyy="8.30592250596926E-05"
        iyz="7.28274909922964E-07"
        izz="0.000146126883741779" />
    </inertial>
    <visual>
      <origin
        xyz="0 0 0"
        rpy="0 0 0" />
      <geometry>
        <mesh
          filename="package://potter_description/meshes/roda_traseira.STL" />
      </geometry>
      <material
        name="">
        <color
          rgba="0.792156862745098 0.819607843137255 0.933333333333333 1" />
      </material>
    </visual>
    <collision>
      <origin
        xyz="0 0 0"
        rpy="0 0 0" />
      <geometry>
        <mesh
          filename="package://potter_description/meshes/roda_traseira.STL" />
      </geometry>
    </collision>
  </link>
  
  <joint
    name="rodatraseira"
    type="revolute">
    <origin
      xyz="0.22766 -0.5673 0"
      rpy="-1.5708 -0.11103 2.7687" />
    <parent
      link="base_link" />
    <child
      link="roda_traseira" />
    <axis
      xyz="0.1108 -0.99384 0" />
    <limit
	    lower="-3.1415926536"
	    upper="3.1415926536"
      effort="10000"
      velocity="10" />
  </joint>
  
  <link name="base_scan">
    <visual>
      <origin xyz="0 0 0.0" rpy="0 0 3.14"/>
      <geometry>
        <mesh filename="package://potter_description/meshes/lds.stl" scale="0.001 0.001 0.001"/>
      </geometry>
      <material name="dark"/>
    </visual>

    <collision>
      <origin xyz="0.015 0 -0.0065" rpy="0 0 3.14"/>
      <geometry>
        <cylinder length="0.0315" radius="0.055"/>
      </geometry>
    </collision>

    <inertial>
      <mass value="0.114" />
      <origin xyz="0 0 0" />
      <inertia ixx="0.001" ixy="0.0" ixz="0.0"
               iyy="0.001" iyz="0.0"
               izz="0.001" />
    </inertial>
  </link>
  
  <joint name="base_scan_joint" type="fixed">
    <origin xyz="-0.30 -0.5673 0.30" rpy="0 0 3.14"/>
    <parent link="base_link"/>
    <child link="base_scan"/>
  </joint>
  
  <link name="kinect_link">
    <visual>
      <origin xyz="0.0 0 0.0" rpy="0 0 0"/>
      <geometry>
        <mesh filename="package://potter_description/meshes/kinect.dae" />
      </geometry>
      <material name="light_black"/>
    </visual>

    <collision>
      <origin xyz="0.0 0 0.00" rpy="0 0 0"/>
      <geometry>
        <box size="0.073000 0.276000 0.072000"/>
      </geometry>
    </collision>

    <inertial>
      <origin xyz="0 0 0" rpy="0 0 0"/>
      <mass value="0.1"/>
      <inertia ixx="2.2124416e-03" ixy="-1.2294101e-05" ixz="3.4938785e-05"
               iyy="2.1193702e-03" iyz="-5.0120904e-06"
               izz="2.0064271e-03" />
    </inertial>
  </link>
  
  <joint name="kinect_joint" type="fixed">
    <parent link="base_link"/>
    <child link="kinect_link"/>
    <origin xyz="-0.3 -0.5673 0.20" rpy="0 0 3.14"/>
  </joint>
  
    <joint name="camera_depth_joint" type="fixed">
    <origin xyz="0 0 0" rpy="-1.57 0 -1.57 "/>
    <parent link="kinect_link"/>
    <child link="camera_depth_link"/>
  </joint>

  <link name="camera_depth_link"></link>
</robot>
